Workbook
Name ba: '[1]BvA Ster Assurance 1110551'!$CW$30:$CZ$30

Sheet Sheet1
B5: FY26 Expenses Budget
B6: Cost Center | C6: 1110551 | D6: {Responsible}
B7: Department | C7: Cybersecurity
G10: FY26 ACTUAL | Z10: FY26 Plan
G12: Jul | H12: Aug | I12: Sep | J12: Oct | K12: Nov | L12: Dec | M12: Jan | N12: Feb | O12: Mar | P12: Apr | Q12: May | R12: Jun | S12: Full Year | Y12: BVA Group | Z12: Jul | AA12: Aug | AB12: Sep | AC12: Oct | AD12: Nov | AE12: Dec | AF12: Jan | AG12: Feb | AH12: Mar | AI12: Apr | AJ12: May | AK12: Jun | AL12: Full Year
F13: Wages & Salaries | G13: =SUMIFS('JDE GL Act'!$H:$H,'JDE GL Act'!$J:$J,$C$6,'JDE GL Act'!$I:$I,G$12,'JDE GL Act'!$L:$L,$F13) -> 71011.94 | H13: =SUMIFS('JDE GL Act'!$H:$H,'JDE GL Act'!$J:$J,$C$6,'JDE GL Act'!$I:$I,H$12,'JDE GL Act'!$L:$L,$F13) -> 69219.31 | I13: =SUMIFS('JDE GL Act'!$H:$H,'JDE GL Act'!$J:$J,$C$6,'JDE GL Act'!$I:$I,I$12,'JDE GL Act'!$L:$L,$F13) -> 0 | J13: =SUMIFS('JDE GL Act'!$H:$H,'JDE GL Act'!$J:$J,$C$6,'JDE GL Act'!$I:$I,J$12,'JDE GL Act'!$L:$L,$F13) -> 0 | K13: =SUMIFS('JDE GL Act'!$H:$H,'JDE GL Act'!$J:$J,$C$6,'JDE GL Act'!$I:$I,K$12,'JDE GL Act'!$L:$L,$F13) -> 0 | L13: =SUMIFS('JDE GL Act'!$H:$H,'JDE GL Act'!$J:$J,$C$6,'JDE GL Act'!$I:$I,L$12,'JDE GL Act'!$L:$L,$F13) -> 0 | M13: =SUMIFS('JDE GL Act'!$H:$H,'JDE GL Act'!$J:$J,$C$6,'JDE GL Act'!$I:$I,M$12,'JDE GL Act'!$L:$L,$F13) -> 0 | N13: =SUMIFS('JDE GL Act'!$H:$H,'JDE GL Act'!$J:$J,$C$6,'JDE GL Act'!$I:$I,N$12,'JDE GL Act'!$L:$L,$F13) -> 0 | ... R13: =SUMIFS('JDE GL Act'!$H:$H,'JDE GL Act'!$J:$J,$C$6,'JDE GL Act'!$I:$I,R$12,'JDE GL Act'!$L:$L,$F13) -> 0 | S13: =+SUM(G13:R13) -> 140231.25 | Y13: =F13 -> Wages & Salaries | Z13: =G13 -> 71011.94 | AA13: =H13 -> 69219.31 | AB13: =SUMIF($Y$32:$Y$104,$Y13,AB$32:AB$104) -> 71599.632 | AC13: =SUMIF($Y$32:$Y$104,$Y13,AC$32:AC$104) -> 74854.161 | AD13: =SUMIF($Y$32:$Y$104,$Y13,AD$32:AD$104) -> 65090.575 | AE13: =SUMIF($Y$32:$Y$104,$Y13,AE$32:AE$104) -> 74854.161 | AF13: =SUMIF($Y$32:$Y$104,$Y13,AF$32:AF$104) -> 71599.632 | AG13: =SUMIF($Y$32:$Y$104,$Y13,AG$32:AG$104) -> 65090.575 | AH13: =SUMIF($Y$32:$Y$104,$Y13,AH$32:AH$104) -> 71599.632 | AI13: =SUMIF($Y$32:$Y$104,$Y13,AI$32:AI$104) -> 71599.632 | ... AL13: =SUMIF($Y$32:$Y$104,$Y13,AL$32:AL$104) -> 843528.29
F14: Overtime | G14: =SUMIFS('JDE GL Act'!$H:$H,'JDE GL Act'!$J:$J,$C$6,'JDE GL Act'!$I:$I,G$12,'JDE GL Act'!$L:$L,$F14) -> 364.21 | H14: =SUMIFS('JDE GL Act'!$H:$H,'JDE GL Act'!$J:$J,$C$6,'JDE GL Act'!$I:$I,H$12,'JDE GL Act'!$L:$L,$F14) -> 27.75 | I14: =SUMIFS('JDE GL Act'!$H:$H,'JDE GL Act'!$J:$J,$C$6,'JDE GL Act'!$I:$I,I$12,'JDE GL Act'!$L:$L,$F14) -> 0 | J14: =SUMIFS('JDE GL Act'!$H:$H,'JDE GL Act'!$J:$J,$C$6,'JDE GL Act'!$I:$I,J$12,'JDE GL Act'!$L:$L,$F14) -> 0 | K14: =SUMIFS('JDE GL Act'!$H:$H,'JDE GL Act'!$J:$J,$C$6,'JDE GL Act'!$I:$I,K$12,'JDE GL Act'!$L:$L,$F14) -> 0 | L14: =SUMIFS('JDE GL Act'!$H:$H,'JDE GL Act'!$J:$J,$C$6,'JDE GL Act'!$I:$I,L$12,'JDE GL Act'!$L:$L,$F14) -> 0 | M14: =SUMIFS('JDE GL Act'!$H:$H,'JDE GL Act'!$J:$J,$C$6,'JDE GL Act'!$I:$I,M$12,'JDE GL Act'!$L:$L,$F14) -> 0 | N14: =SUMIFS('JDE GL Act'!$H:$H,'JDE GL Act'!$J:$J,$C$6,'JDE GL Act'!$I:$I,N$12,'JDE GL Act'!$L:$L,$F14) -> 0 | ... R14: =SUMIFS('JDE GL Act'!$H:$H,'JDE GL Act'!$J:$J,$C$6,'JDE GL Act'!$I:$I,R$12,'JDE GL Act'!$L:$L,$F14) -> 0 | S14: =+SUM(G14:R14) -> 391.96 | Y14: =F14 -> Overtime | Z14: =G14 -> 364.21 | AA14: =H14 -> 27.75 | AB14: =SUMIF($Y$32:$Y$104,$Y14,AB$32:AB$104) -> 640.40415 | AC14: =SUMIF($Y$32:$Y$104,$Y14,AC$32:AC$104) -> 669.51343 | AD14: =SUMIF($Y$32:$Y$104,$Y14,AD$32:AD$104) -> 582.18559 | AE14: =SUMIF($Y$32:$Y$104,$Y14,AE$32:AE$104) -> 669.51343 | AF14: =SUMIF($Y$32:$Y$104,$Y14,AF$32:AF$104) -> 640.40415 | AG14: =SUMIF($Y$32:$Y$104,$Y14,AG$32:AG$104) -> 582.18559 | AH14: =SUMIF($Y$32:$Y$104,$Y14,AH$32:AH$104) -> 640.40415 | AI14: =SUMIF($Y$32:$Y$104,$Y14,AI$32:AI$104) -> 640.40415 | ... AL14: =SUMIF($Y$32:$Y$104,$Y14,AL$32:AL$104) -> 7544.7178
F15: Fringe Benefits | G15: =SUMIFS('JDE GL Act'!$H:$H,'JDE GL Act'!$J:$J,$C$6,'JDE GL Act'!$I:$I,G$12,'JDE GL Act'!$L:$L,$F15) -> 26853.89 | H15: =SUMIFS('JDE GL Act'!$H:$H,'JDE GL Act'!$J:$J,$C$6,'JDE GL Act'!$I:$I,H$12,'JDE GL Act'!$L:$L,$F15) -> 22212.77 | I15: =SUMIFS('JDE GL Act'!$H:$H,'JDE GL Act'!$J:$J,$C$6,'JDE GL Act'!$I:$I,I$12,'JDE GL Act'!$L:$L,$F15) -> 0 | J15: =SUMIFS('JDE GL Act'!$H:$H,'JDE GL Act'!$J:$J,$C$6,'JDE GL Act'!$I:$I,J$12,'JDE GL Act'!$L:$L,$F15) -> 0 | K15: =SUMIFS('JDE GL Act'!$H:$H,'JDE GL Act'!$J:$J,$C$6,'JDE GL Act'!$I:$I,K$12,'JDE GL Act'!$L:$L,$F15) -> 0 | L15: =SUMIFS('JDE GL Act'!$H:$H,'JDE GL Act'!$J:$J,$C$6,'JDE GL Act'!$I:$I,L$12,'JDE GL Act'!$L:$L,$F15) -> 0 | M15: =SUMIFS('JDE GL Act'!$H:$H,'JDE GL Act'!$J:$J,$C$6,'JDE GL Act'!$I:$I,M$12,'JDE GL Act'!$L:$L,$F15) -> 0 | N15: =SUMIFS('JDE GL Act'!$H:$H,'JDE GL Act'!$J:$J,$C$6,'JDE GL Act'!$I:$I,N$12,'JDE GL Act'!$L:$L,$F15) -> 0 | ... R15: =SUMIFS('JDE GL Act'!$H:$H,'JDE GL Act'!$J:$J,$C$6,'JDE GL Act'!$I:$I,R$12,'JDE GL Act'!$L:$L,$F15) -> 0 | S15: =+SUM(G15:R15) -> 49066.66 | Y15: =F15 -> Fringe Benefits | Z15: =G15 -> 26853.89 | AA15: =H15 -> 22212.77 | AB15: =SUMIF($Y$32:$Y$104,$Y15,AB$32:AB$104) -> 24862.473 | AC15: =SUMIF($Y$32:$Y$104,$Y15,AC$32:AC$104) -> 24463.949 | AD15: =SUMIF($Y$32:$Y$104,$Y15,AD$32:AD$104) -> 21391.26 | AE15: =SUMIF($Y$32:$Y$104,$Y15,AE$32:AE$104) -> 22872.355 | AF15: =SUMIF($Y$32:$Y$104,$Y15,AF$32:AF$104) -> 27719.847 | AG15: =SUMIF($Y$32:$Y$104,$Y15,AG$32:AG$104) -> 23113.689 | AH15: =SUMIF($Y$32:$Y$104,$Y15,AH$32:AH$104) -> 24862.473 | AI15: =SUMIF($Y$32:$Y$104,$Y15,AI$32:AI$104) -> 24889.012 | ... AL15: =SUMIF($Y$32:$Y$104,$Y15,AL$32:AL$104) -> 291159.4
F16: Employee Related Expenses | G16: =SUMIFS('JDE GL Act'!$H:$H,'JDE GL Act'!$J:$J,$C$6,'JDE GL Act'!$I:$I,G$12,'JDE GL Act'!$L:$L,$F16) -> 0 | H16: =SUMIFS('JDE GL Act'!$H:$H,'JDE GL Act'!$J:$J,$C$6,'JDE GL Act'!$I:$I,H$12,'JDE GL Act'!$L:$L,$F16) -> 0 | I16: =SUMIFS('JDE GL Act'!$H:$H,'JDE GL Act'!$J:$J,$C$6,'JDE GL Act'!$I:$I,I$12,'JDE GL Act'!$L:$L,$F16) -> 0 | J16: =SUMIFS('JDE GL Act'!$H:$H,'JDE GL Act'!$J:$J,$C$6,'JDE GL Act'!$I:$I,J$12,'JDE GL Act'!$L:$L,$F16) -> 0 | K16: =SUMIFS('JDE GL Act'!$H:$H,'JDE GL Act'!$J:$J,$C$6,'JDE GL Act'!$I:$I,K$12,'JDE GL Act'!$L:$L,$F16) -> 0 | L16: =SUMIFS('JDE GL Act'!$H:$H,'JDE GL Act'!$J:$J,$C$6,'JDE GL Act'!$I:$I,L$12,'JDE GL Act'!$L:$L,$F16) -> 0 | M16: =SUMIFS('JDE GL Act'!$H:$H,'JDE GL Act'!$J:$J,$C$6,'JDE GL Act'!$I:$I,M$12,'JDE GL Act'!$L:$L,$F16) -> 0 | N16: =SUMIFS('JDE GL Act'!$H:$H,'JDE GL Act'!$J:$J,$C$6,'JDE GL Act'!$I:$I,N$12,'JDE GL Act'!$L:$L,$F16) -> 0 | ... R16: =SUMIFS('JDE GL Act'!$H:$H,'JDE GL Act'!$J:$J,$C$6,'JDE GL Act'!$I:$I,R$12,'JDE GL Act'!$L:$L,$F16) -> 0 | S16: =+SUM(G16:R16) -> 0 | Y16: =F16 -> Employee Related Expenses | Z16: =G16 -> 0 | AA16: =H16 -> 0 | AB16: =SUMIF($Y$32:$Y$104,$Y16,AB$32:AB$104) -> 0 | AC16: =SUMIF($Y$32:$Y$104,$Y16,AC$32:AC$104) -> 0 | AD16: =SUMIF($Y$32:$Y$104,$Y16,AD$32:AD$104) -> 0 | AE16: =SUMIF($Y$32:$Y$104,$Y16,AE$32:AE$104) -> 0 | AF16: =SUMIF($Y$32:$Y$104,$Y16,AF$32:AF$104) -> 0 | AG16: =SUMIF($Y$32:$Y$104,$Y16,AG$32:AG$104) -> 3000 | AH16: =SUMIF($Y$32:$Y$104,$Y16,AH$32:AH$104) -> 0 | AI16: =SUMIF($Y$32:$Y$104,$Y16,AI$32:AI$104) -> 0 | ... AL16: =SUMIF($Y$32:$Y$104,$Y16,AL$32:AL$104) -> 67500
F17: Travel & Entertainment | G17: =SUMIFS('JDE GL Act'!$H:$H,'JDE GL Act'!$J:$J,$C$6,'JDE GL Act'!$I:$I,G$12,'JDE GL Act'!$L:$L,$F17) -> 907.76 | H17: =SUMIFS('JDE GL Act'!$H:$H,'JDE GL Act'!$J:$J,$C$6,'JDE GL Act'!$I:$I,H$12,'JDE GL Act'!$L:$L,$F17) -> 2362.91 | I17: =SUMIFS('JDE GL Act'!$H:$H,'JDE GL Act'!$J:$J,$C$6,'JDE GL Act'!$I:$I,I$12,'JDE GL Act'!$L:$L,$F17) -> 0 | J17: =SUMIFS('JDE GL Act'!$H:$H,'JDE GL Act'!$J:$J,$C$6,'JDE GL Act'!$I:$I,J$12,'JDE GL Act'!$L:$L,$F17) -> 0 | K17: =SUMIFS('JDE GL Act'!$H:$H,'JDE GL Act'!$J:$J,$C$6,'JDE GL Act'!$I:$I,K$12,'JDE GL Act'!$L:$L,$F17) -> 0 | L17: =SUMIFS('JDE GL Act'!$H:$H,'JDE GL Act'!$J:$J,$C$6,'JDE GL Act'!$I:$I,L$12,'JDE GL Act'!$L:$L,$F17) -> 0 | M17: =SUMIFS('JDE GL Act'!$H:$H,'JDE GL Act'!$J:$J,$C$6,'JDE GL Act'!$I:$I,M$12,'JDE GL Act'!$L:$L,$F17) -> 0 | N17: =SUMIFS('JDE GL Act'!$H:$H,'JDE GL Act'!$J:$J,$C$6,'JDE GL Act'!$I:$I,N$12,'JDE GL Act'!$L:$L,$F17) -> 0 | ... R17: =SUMIFS('JDE GL Act'!$H:$H,'JDE GL Act'!$J:$J,$C$6,'JDE GL Act'!$I:$I,R$12,'JDE GL Act'!$L:$L,$F17) -> 0 | S17: =+SUM(G17:R17) -> 3270.67 | Y17: =F17 -> Travel & Entertainment | Z17: =G17 -> 907.76 | AA17: =H17 -> 2362.91 | AB17: =SUMIF($Y$32:$Y$104,$Y17,AB$32:AB$104) -> 1770 | AC17: =SUMIF($Y$32:$Y$104,$Y17,AC$32:AC$104) -> 1770 | AD17: =SUMIF($Y$32:$Y$104,$Y17,AD$32:AD$104) -> 0 | AE17: =SUMIF($Y$32:$Y$104,$Y17,AE$32:AE$104) -> 0 | AF17: =SUMIF($Y$32:$Y$104,$Y17,AF$32:AF$104) -> 0 | AG17: =SUMIF($Y$32:$Y$104,$Y17,AG$32:AG$104) -> 0 | AH17: =SUMIF($Y$32:$Y$104,$Y17,AH$32:AH$104) -> 1770 | AI17: =SUMIF($Y$32:$Y$104,$Y17,AI$32:AI$104) -> 0 | ... AL17: =SUMIF($Y$32:$Y$104,$Y17,AL$32:AL$104) -> 7080
F18: Supplies Expenses | G18: =SUMIFS('JDE GL Act'!$H:$H,'JDE GL Act'!$J:$J,$C$6,'JDE GL Act'!$I:$I,G$12,'JDE GL Act'!$L:$L,$F18) -> -2291.94 | H18: =SUMIFS('JDE GL Act'!$H:$H,'JDE GL Act'!$J:$J,$C$6,'JDE GL Act'!$I:$I,H$12,'JDE GL Act'!$L:$L,$F18) -> 5983.69 | I18: =SUMIFS('JDE GL Act'!$H:$H,'JDE GL Act'!$J:$J,$C$6,'JDE GL Act'!$I:$I,I$12,'JDE GL Act'!$L:$L,$F18) -> 0 | J18: =SUMIFS('JDE GL Act'!$H:$H,'JDE GL Act'!$J:$J,$C$6,'JDE GL Act'!$I:$I,J$12,'JDE GL Act'!$L:$L,$F18) -> 0 | K18: =SUMIFS('JDE GL Act'!$H:$H,'JDE GL Act'!$J:$J,$C$6,'JDE GL Act'!$I:$I,K$12,'JDE GL Act'!$L:$L,$F18) -> 0 | L18: =SUMIFS('JDE GL Act'!$H:$H,'JDE GL Act'!$J:$J,$C$6,'JDE GL Act'!$I:$I,L$12,'JDE GL Act'!$L:$L,$F18) -> 0 | M18: =SUMIFS('JDE GL Act'!$H:$H,'JDE GL Act'!$J:$J,$C$6,'JDE GL Act'!$I:$I,M$12,'JDE GL Act'!$L:$L,$F18) -> 0 | N18: =SUMIFS('JDE GL Act'!$H:$H,'JDE GL Act'!$J:$J,$C$6,'JDE GL Act'!$I:$I,N$12,'JDE GL Act'!$L:$L,$F18) -> 0 | ... R18: =SUMIFS('JDE GL Act'!$H:$H,'JDE GL Act'!$J:$J,$C$6,'JDE GL Act'!$I:$I,R$12,'JDE GL Act'!$L:$L,$F18) -> 0 | S18: =+SUM(G18:R18) -> 3691.75 | Y18: =F18 -> Supplies Expenses | Z18: =G18 -> -2291.94 | AA18: =H18 -> 5983.69 | AB18: =SUMIF($Y$32:$Y$104,$Y18,AB$32:AB$104) -> 1900 | AC18: =SUMIF($Y$32:$Y$104,$Y18,AC$32:AC$104) -> 800 | AD18: =SUMIF($Y$32:$Y$104,$Y18,AD$32:AD$104) -> 900 | AE18: =SUMIF($Y$32:$Y$104,$Y18,AE$32:AE$104) -> 2400 | AF18: =SUMIF($Y$32:$Y$104,$Y18,AF$32:AF$104) -> 1100 | AG18: =SUMIF($Y$32:$Y$104,$Y18,AG$32:AG$104) -> 800 | AH18: =SUMIF($Y$32:$Y$104,$Y18,AH$32:AH$104) -> 1000 | AI18: =SUMIF($Y$32:$Y$104,$Y18,AI$32:AI$104) -> 800 | ... AL18: =SUMIF($Y$32:$Y$104,$Y18,AL$32:AL$104) -> 28300
F19: Repairs & Maintenance | G19: =SUMIFS('JDE GL Act'!$H:$H,'JDE GL Act'!$J:$J,$C$6,'JDE GL Act'!$I:$I,G$12,'JDE GL Act'!$L:$L,$F19) -> 0 | H19: =SUMIFS('JDE GL Act'!$H:$H,'JDE GL Act'!$J:$J,$C$6,'JDE GL Act'!$I:$I,H$12,'JDE GL Act'!$L:$L,$F19) -> 0 | I19: =SUMIFS('JDE GL Act'!$H:$H,'JDE GL Act'!$J:$J,$C$6,'JDE GL Act'!$I:$I,I$12,'JDE GL Act'!$L:$L,$F19) -> 0 | J19: =SUMIFS('JDE GL Act'!$H:$H,'JDE GL Act'!$J:$J,$C$6,'JDE GL Act'!$I:$I,J$12,'JDE GL Act'!$L:$L,$F19) -> 0 | K19: =SUMIFS('JDE GL Act'!$H:$H,'JDE GL Act'!$J:$J,$C$6,'JDE GL Act'!$I:$I,K$12,'JDE GL Act'!$L:$L,$F19) -> 0 | L19: =SUMIFS('JDE GL Act'!$H:$H,'JDE GL Act'!$J:$J,$C$6,'JDE GL Act'!$I:$I,L$12,'JDE GL Act'!$L:$L,$F19) -> 0 | M19: =SUMIFS('JDE GL Act'!$H:$H,'JDE GL Act'!$J:$J,$C$6,'JDE GL Act'!$I:$I,M$12,'JDE GL Act'!$L:$L,$F19) -> 0 | N19: =SUMIFS('JDE GL Act'!$H:$H,'JDE GL Act'!$J:$J,$C$6,'JDE GL Act'!$I:$I,N$12,'JDE GL Act'!$L:$L,$F19) -> 0 | ... R19: =SUMIFS('JDE GL Act'!$H:$H,'JDE GL Act'!$J:$J,$C$6,'JDE GL Act'!$I:$I,R$12,'JDE GL Act'!$L:$L,$F19) -> 0 | S19: =+SUM(G19:R19) -> 0 | Y19: =F19 -> Repairs & Maintenance | Z19: =G19 -> 0 | AA19: =H19 -> 0 | AB19: =SUMIF($Y$32:$Y$104,$Y19,AB$32:AB$104) -> 0 | AC19: =SUMIF($Y$32:$Y$104,$Y19,AC$32:AC$104) -> 0 | AD19: =SUMIF($Y$32:$Y$104,$Y19,AD$32:AD$104) -> 0 | AE19: =SUMIF($Y$32:$Y$104,$Y19,AE$32:AE$104) -> 0 | AF19: =SUMIF($Y$32:$Y$104,$Y19,AF$32:AF$104) -> 0 | AG19: =SUMIF($Y$32:$Y$104,$Y19,AG$32:AG$104) -> 0 | AH19: =SUMIF($Y$32:$Y$104,$Y19,AH$32:AH$104) -> 0 | AI19: =SUMIF($Y$32:$Y$104,$Y19,AI$32:AI$104) -> 0 | ... AL19: =SUMIF($Y$32:$Y$104,$Y19,AL$32:AL$104) -> 0
F20: Utilities | G20: =SUMIFS('JDE GL Act'!$H:$H,'JDE GL Act'!$J:$J,$C$6,'JDE GL Act'!$I:$I,G$12,'JDE GL Act'!$L:$L,$F20) -> 0 | H20: =SUMIFS('JDE GL Act'!$H:$H,'JDE GL Act'!$J:$J,$C$6,'JDE GL Act'!$I:$I,H$12,'JDE GL Act'!$L:$L,$F20) -> 0 | I20: =SUMIFS('JDE GL Act'!$H:$H,'JDE GL Act'!$J:$J,$C$6,'JDE GL Act'!$I:$I,I$12,'JDE GL Act'!$L:$L,$F20) -> 0 | J20: =SUMIFS('JDE GL Act'!$H:$H,'JDE GL Act'!$J:$J,$C$6,'JDE GL Act'!$I:$I,J$12,'JDE GL Act'!$L:$L,$F20) -> 0 | K20: =SUMIFS('JDE GL Act'!$H:$H,'JDE GL Act'!$J:$J,$C$6,'JDE GL Act'!$I:$I,K$12,'JDE GL Act'!$L:$L,$F20) -> 0 | L20: =SUMIFS('JDE GL Act'!$H:$H,'JDE GL Act'!$J:$J,$C$6,'JDE GL Act'!$I:$I,L$12,'JDE GL Act'!$L:$L,$F20) -> 0 | M20: =SUMIFS('JDE GL Act'!$H:$H,'JDE GL Act'!$J:$J,$C$6,'JDE GL Act'!$I:$I,M$12,'JDE GL Act'!$L:$L,$F20) -> 0 | N20: =SUMIFS('JDE GL Act'!$H:$H,'JDE GL Act'!$J:$J,$C$6,'JDE GL Act'!$I:$I,N$12,'JDE GL Act'!$L:$L,$F20) -> 0 | ... R20: =SUMIFS('JDE GL Act'!$H:$H,'JDE GL Act'!$J:$J,$C$6,'JDE GL Act'!$I:$I,R$12,'JDE GL Act'!$L:$L,$F20) -> 0 | S20: =+SUM(G20:R20) -> 0 | Y20: =F20 -> Utilities | Z20: =G20 -> 0 | AA20: =H20 -> 0 | AB20: =SUMIF($Y$32:$Y$104,$Y20,AB$32:AB$104) -> 0 | AC20: =SUMIF($Y$32:$Y$104,$Y20,AC$32:AC$104) -> 0 | AD20: =SUMIF($Y$32:$Y$104,$Y20,AD$32:AD$104) -> 0 | AE20: =SUMIF($Y$32:$Y$104,$Y20,AE$32:AE$104) -> 0 | AF20: =SUMIF($Y$32:$Y$104,$Y20,AF$32:AF$104) -> 0 | AG20: =SUMIF($Y$32:$Y$104,$Y20,AG$32:AG$104) -> 0 | AH20: =SUMIF($Y$32:$Y$104,$Y20,AH$32:AH$104) -> 0 | AI20: =SUMIF($Y$32:$Y$104,$Y20,AI$32:AI$104) -> 0 | ... AL20: =SUMIF($Y$32:$Y$104,$Y20,AL$32:AL$104) -> 0
F21: Outside Services | G21: =SUMIFS('JDE GL Act'!$H:$H,'JDE GL Act'!$J:$J,$C$6,'JDE GL Act'!$I:$I,G$12,'JDE GL Act'!$L:$L,$F21) -> 42145.78 | H21: =SUMIFS('JDE GL Act'!$H:$H,'JDE GL Act'!$J:$J,$C$6,'JDE GL Act'!$I:$I,H$12,'JDE GL Act'!$L:$L,$F21) -> 9676.38 | I21: =SUMIFS('JDE GL Act'!$H:$H,'JDE GL Act'!$J:$J,$C$6,'JDE GL Act'!$I:$I,I$12,'JDE GL Act'!$L:$L,$F21) -> 0 | J21: =SUMIFS('JDE GL Act'!$H:$H,'JDE GL Act'!$J:$J,$C$6,'JDE GL Act'!$I:$I,J$12,'JDE GL Act'!$L:$L,$F21) -> 0 | K21: =SUMIFS('JDE GL Act'!$H:$H,'JDE GL Act'!$J:$J,$C$6,'JDE GL Act'!$I:$I,K$12,'JDE GL Act'!$L:$L,$F21) -> 0 | L21: =SUMIFS('JDE GL Act'!$H:$H,'JDE GL Act'!$J:$J,$C$6,'JDE GL Act'!$I:$I,L$12,'JDE GL Act'!$L:$L,$F21) -> 0 | M21: =SUMIFS('JDE GL Act'!$H:$H,'JDE GL Act'!$J:$J,$C$6,'JDE GL Act'!$I:$I,M$12,'JDE GL Act'!$L:$L,$F21) -> 0 | N21: =SUMIFS('JDE GL Act'!$H:$H,'JDE GL Act'!$J:$J,$C$6,'JDE GL Act'!$I:$I,N$12,'JDE GL Act'!$L:$L,$F21) -> 0 | ... R21: =SUMIFS('JDE GL Act'!$H:$H,'JDE GL Act'!$J:$J,$C$6,'JDE GL Act'!$I:$I,R$12,'JDE GL Act'!$L:$L,$F21) -> 0 | S21: =+SUM(G21:R21) -> 51822.16 | Y21: =F21 -> Outside Services | Z21: =G21 -> 42145.78 | AA21: =H21 -> 9676.38 | AB21: =SUMIF($Y$32:$Y$104,$Y21,AB$32:AB$104) -> 76800 | AC21: =SUMIF($Y$32:$Y$104,$Y21,AC$32:AC$104) -> 16500 | AD21: =SUMIF($Y$32:$Y$104,$Y21,AD$32:AD$104) -> 56500 | AE21: =SUMIF($Y$32:$Y$104,$Y21,AE$32:AE$104) -> 65900 | AF21: =SUMIF($Y$32:$Y$104,$Y21,AF$32:AF$104) -> 24400 | AG21: =SUMIF($Y$32:$Y$104,$Y21,AG$32:AG$104) -> 41850 | AH21: =SUMIF($Y$32:$Y$104,$Y21,AH$32:AH$104) -> 90300 | AI21: =SUMIF($Y$32:$Y$104,$Y21,AI$32:AI$104) -> 28400 | ... AL21: =SUMIF($Y$32:$Y$104,$Y21,AL$32:AL$104) -> 654750
F22: Inbound Freight | G22: =SUMIFS('JDE GL Act'!$H:$H,'JDE GL Act'!$J:$J,$C$6,'JDE GL Act'!$I:$I,G$12,'JDE GL Act'!$L:$L,$F22) -> 34.45 | H22: =SUMIFS('JDE GL Act'!$H:$H,'JDE GL Act'!$J:$J,$C$6,'JDE GL Act'!$I:$I,H$12,'JDE GL Act'!$L:$L,$F22) -> 0 | I22: =SUMIFS('JDE GL Act'!$H:$H,'JDE GL Act'!$J:$J,$C$6,'JDE GL Act'!$I:$I,I$12,'JDE GL Act'!$L:$L,$F22) -> 0 | J22: =SUMIFS('JDE GL Act'!$H:$H,'JDE GL Act'!$J:$J,$C$6,'JDE GL Act'!$I:$I,J$12,'JDE GL Act'!$L:$L,$F22) -> 0 | K22: =SUMIFS('JDE GL Act'!$H:$H,'JDE GL Act'!$J:$J,$C$6,'JDE GL Act'!$I:$I,K$12,'JDE GL Act'!$L:$L,$F22) -> 0 | L22: =SUMIFS('JDE GL Act'!$H:$H,'JDE GL Act'!$J:$J,$C$6,'JDE GL Act'!$I:$I,L$12,'JDE GL Act'!$L:$L,$F22) -> 0 | M22: =SUMIFS('JDE GL Act'!$H:$H,'JDE GL Act'!$J:$J,$C$6,'JDE GL Act'!$I:$I,M$12,'JDE GL Act'!$L:$L,$F22) -> 0 | N22: =SUMIFS('JDE GL Act'!$H:$H,'JDE GL Act'!$J:$J,$C$6,'JDE GL Act'!$I:$I,N$12,'JDE GL Act'!$L:$L,$F22) -> 0 | ... R22: =SUMIFS('JDE GL Act'!$H:$H,'JDE GL Act'!$J:$J,$C$6,'JDE GL Act'!$I:$I,R$12,'JDE GL Act'!$L:$L,$F22) -> 0 | S22: =+SUM(G22:R22) -> 34.45 | Y22: =F22 -> Inbound Freight | Z22: =G22 -> 34.45 | AA22: =H22 -> 0 | AB22: =SUMIF($Y$32:$Y$104,$Y22,AB$32:AB$104) -> 0 | AC22: =SUMIF($Y$32:$Y$104,$Y22,AC$32:AC$104) -> 0 | AD22: =SUMIF($Y$32:$Y$104,$Y22,AD$32:AD$104) -> 0 | AE22: =SUMIF($Y$32:$Y$104,$Y22,AE$32:AE$104) -> 0 | AF22: =SUMIF($Y$32:$Y$104,$Y22,AF$32:AF$104) -> 0 | AG22: =SUMIF($Y$32:$Y$104,$Y22,AG$32:AG$104) -> 0 | AH22: =SUMIF($Y$32:$Y$104,$Y22,AH$32:AH$104) -> 0 | AI22: =SUMIF($Y$32:$Y$104,$Y22,AI$32:AI$104) -> 0 | ... AL22: =SUMIF($Y$32:$Y$104,$Y22,AL$32:AL$104) -> 0
F23: Other | G23: =SUMIFS('JDE GL Act'!$H:$H,'JDE GL Act'!$J:$J,$C$6,'JDE GL Act'!$I:$I,G$12,'JDE GL Act'!$L:$L,$F23) -> 8.67 | H23: =SUMIFS('JDE GL Act'!$H:$H,'JDE GL Act'!$J:$J,$C$6,'JDE GL Act'!$I:$I,H$12,'JDE GL Act'!$L:$L,$F23) -> 0 | I23: =SUMIFS('JDE GL Act'!$H:$H,'JDE GL Act'!$J:$J,$C$6,'JDE GL Act'!$I:$I,I$12,'JDE GL Act'!$L:$L,$F23) -> 0 | J23: =SUMIFS('JDE GL Act'!$H:$H,'JDE GL Act'!$J:$J,$C$6,'JDE GL Act'!$I:$I,J$12,'JDE GL Act'!$L:$L,$F23) -> 0 | K23: =SUMIFS('JDE GL Act'!$H:$H,'JDE GL Act'!$J:$J,$C$6,'JDE GL Act'!$I:$I,K$12,'JDE GL Act'!$L:$L,$F23) -> 0 | L23: =SUMIFS('JDE GL Act'!$H:$H,'JDE GL Act'!$J:$J,$C$6,'JDE GL Act'!$I:$I,L$12,'JDE GL Act'!$L:$L,$F23) -> 0 | M23: =SUMIFS('JDE GL Act'!$H:$H,'JDE GL Act'!$J:$J,$C$6,'JDE GL Act'!$I:$I,M$12,'JDE GL Act'!$L:$L,$F23) -> 0 | N23: =SUMIFS('JDE GL Act'!$H:$H,'JDE GL Act'!$J:$J,$C$6,'JDE GL Act'!$I:$I,N$12,'JDE GL Act'!$L:$L,$F23) -> 0 | ... R23: =SUMIFS('JDE GL Act'!$H:$H,'JDE GL Act'!$J:$J,$C$6,'JDE GL Act'!$I:$I,R$12,'JDE GL Act'!$L:$L,$F23) -> 0 | S23: =+SUM(G23:R23) -> 8.67 | Y23: =F23 -> Other | Z23: =G23 -> 8.67 | AA23: =H23 -> 0 | AB23: =SUMIF($Y$32:$Y$104,$Y23,AB$32:AB$104) -> 0 | AC23: =SUMIF($Y$32:$Y$104,$Y23,AC$32:AC$104) -> 0 | AD23: =SUMIF($Y$32:$Y$104,$Y23,AD$32:AD$104) -> 0 | AE23: =SUMIF($Y$32:$Y$104,$Y23,AE$32:AE$104) -> 0 | AF23: =SUMIF($Y$32:$Y$104,$Y23,AF$32:AF$104) -> 0 | AG23: =SUMIF($Y$32:$Y$104,$Y23,AG$32:AG$104) -> 0 | AH23: =SUMIF($Y$32:$Y$104,$Y23,AH$32:AH$104) -> 0 | AI23: =SUMIF($Y$32:$Y$104,$Y23,AI$32:AI$104) -> 0 | ... AL23: =SUMIF($Y$32:$Y$104,$Y23,AL$32:AL$104) -> 1000
F24: Total Controllable | G24: =SUM(G13:G23) -> 139034.76 | H24: =SUM(H13:H23) -> 109482.81 | I24: =SUM(I13:I23) -> 0 | J24: =SUM(J13:J23) -> 0 | K24: =SUM(K13:K23) -> 0 | L24: =SUM(L13:L23) -> 0 | M24: =SUM(M13:M23) -> 0 | N24: =SUM(N13:N23) -> 0 | ... R24: =SUM(R13:R23) -> 0 | S24: =+SUM(G24:R24) -> 248517.57 | Y24: =F24 -> Total Controllable | Z24: =G24 -> 139034.76 | AA24: =H24 -> 109482.81 | AB24: =SUM(AB13:AB23) -> 177572.51 | AC24: =SUM(AC13:AC23) -> 119057.62 | AD24: =SUM(AD13:AD23) -> 144464.02 | AE24: =SUM(AE13:AE23) -> 166696.03 | AF24: =SUM(AF13:AF23) -> 125459.88 | AG24: =SUM(AG13:AG23) -> 134436.45 | AH24: =SUM(AH13:AH23) -> 190172.51 | AI24: =SUM(AI13:AI23) -> 126329.05 | ... AL24: =SUM(AL13:AL23) -> 1900862.4
F25: Depreciation | G25: =SUMIFS('JDE GL Act'!$H:$H,'JDE GL Act'!$J:$J,$C$6,'JDE GL Act'!$I:$I,G$12,'JDE GL Act'!$L:$L,$F25) -> 1545.11 | H25: =SUMIFS('JDE GL Act'!$H:$H,'JDE GL Act'!$J:$J,$C$6,'JDE GL Act'!$I:$I,H$12,'JDE GL Act'!$L:$L,$F25) -> 1545.12 | I25: =SUMIFS('JDE GL Act'!$H:$H,'JDE GL Act'!$J:$J,$C$6,'JDE GL Act'!$I:$I,I$12,'JDE GL Act'!$L:$L,$F25) -> 0 | J25: =SUMIFS('JDE GL Act'!$H:$H,'JDE GL Act'!$J:$J,$C$6,'JDE GL Act'!$I:$I,J$12,'JDE GL Act'!$L:$L,$F25) -> 0 | K25: =SUMIFS('JDE GL Act'!$H:$H,'JDE GL Act'!$J:$J,$C$6,'JDE GL Act'!$I:$I,K$12,'JDE GL Act'!$L:$L,$F25) -> 0 | L25: =SUMIFS('JDE GL Act'!$H:$H,'JDE GL Act'!$J:$J,$C$6,'JDE GL Act'!$I:$I,L$12,'JDE GL Act'!$L:$L,$F25) -> 0 | M25: =SUMIFS('JDE GL Act'!$H:$H,'JDE GL Act'!$J:$J,$C$6,'JDE GL Act'!$I:$I,M$12,'JDE GL Act'!$L:$L,$F25) -> 0 | N25: =SUMIFS('JDE GL Act'!$H:$H,'JDE GL Act'!$J:$J,$C$6,'JDE GL Act'!$I:$I,N$12,'JDE GL Act'!$L:$L,$F25) -> 0 | ... R25: =SUMIFS('JDE GL Act'!$H:$H,'JDE GL Act'!$J:$J,$C$6,'JDE GL Act'!$I:$I,R$12,'JDE GL Act'!$L:$L,$F25) -> 0 | S25: =+SUM(G25:R25) -> 3090.23 | Y25: =F25 -> Depreciation | Z25: =G25 -> 1545.11 | AA25: =H25 -> 1545.12 | AB25: =SUMIF($Y$32:$Y$104,$Y25,AB$32:AB$104) -> 0 | AC25: =SUMIF($Y$32:$Y$104,$Y25,AC$32:AC$104) -> 0 | AD25: =SUMIF($Y$32:$Y$104,$Y25,AD$32:AD$104) -> 0 | AE25: =SUMIF($Y$32:$Y$104,$Y25,AE$32:AE$104) -> 0 | AF25: =SUMIF($Y$32:$Y$104,$Y25,AF$32:AF$104) -> 0 | AG25: =SUMIF($Y$32:$Y$104,$Y25,AG$32:AG$104) -> 0 | AH25: =SUMIF($Y$32:$Y$104,$Y25,AH$32:AH$104) -> 0 | AI25: =SUMIF($Y$32:$Y$104,$Y25,AI$32:AI$104) -> 0 | ... AL25: =SUMIF($Y$32:$Y$104,$Y25,AL$32:AL$104) -> 0
F26: Total Spending | G26: =+G24+G25 -> 140579.87 | H26: =+H24+H25 -> 111027.93 | I26: =+I24+I25 -> 0 | J26: =+J24+J25 -> 0 | K26: =+K24+K25 -> 0 | L26: =+L24+L25 -> 0 | M26: =+M24+M25 -> 0 | N26: =+N24+N25 -> 0 | ... R26: =+R24+R25 -> 0 | S26: =+SUM(G26:R26) -> 251607.8 | Y26: =F26 -> Total Spending | Z26: =G26 -> 140579.87 | AA26: =H26 -> 111027.93 | AB26: =+AB24+AB25 -> 177572.51 | AC26: =+AC24+AC25 -> 119057.62 | AD26: =+AD24+AD25 -> 144464.02 | AE26: =+AE24+AE25 -> 166696.03 | AF26: =+AF24+AF25 -> 125459.88 | AG26: =+AG24+AG25 -> 134436.45 | AH26: =+AH24+AH25 -> 190172.51 | AI26: =+AI24+AI25 -> 126329.05 | ... AL26: =+AL24+AL25 -> 1900862.4
F27: Appropriation Expense | G27: =SUMIFS('JDE GL Act'!$H:$H,'JDE GL Act'!$J:$J,$C$6,'JDE GL Act'!$I:$I,G$12,'JDE GL Act'!$L:$L,$F27) -> 0 | H27: =SUMIFS('JDE GL Act'!$H:$H,'JDE GL Act'!$J:$J,$C$6,'JDE GL Act'!$I:$I,H$12,'JDE GL Act'!$L:$L,$F27) -> 0 | I27: =SUMIFS('JDE GL Act'!$H:$H,'JDE GL Act'!$J:$J,$C$6,'JDE GL Act'!$I:$I,I$12,'JDE GL Act'!$L:$L,$F27) -> 0 | J27: =SUMIFS('JDE GL Act'!$H:$H,'JDE GL Act'!$J:$J,$C$6,'JDE GL Act'!$I:$I,J$12,'JDE GL Act'!$L:$L,$F27) -> 0 | K27: =SUMIFS('JDE GL Act'!$H:$H,'JDE GL Act'!$J:$J,$C$6,'JDE GL Act'!$I:$I,K$12,'JDE GL Act'!$L:$L,$F27) -> 0 | L27: =SUMIFS('JDE GL Act'!$H:$H,'JDE GL Act'!$J:$J,$C$6,'JDE GL Act'!$I:$I,L$12,'JDE GL Act'!$L:$L,$F27) -> 0 | M27: =SUMIFS('JDE GL Act'!$H:$H,'JDE GL Act'!$J:$J,$C$6,'JDE GL Act'!$I:$I,M$12,'JDE GL Act'!$L:$L,$F27) -> 0 | N27: =SUMIFS('JDE GL Act'!$H:$H,'JDE GL Act'!$J:$J,$C$6,'JDE GL Act'!$I:$I,N$12,'JDE GL Act'!$L:$L,$F27) -> 0 | ... R27: =SUMIFS('JDE GL Act'!$H:$H,'JDE GL Act'!$J:$J,$C$6,'JDE GL Act'!$I:$I,R$12,'JDE GL Act'!$L:$L,$F27) -> 0 | S27: =+SUM(G27:R27) -> 0 | Y27: =F27 -> Appropriation Expense | Z27: =G27 -> 0 | AA27: =H27 -> 0 | AB27: =SUMIF($Y$32:$Y$104,$Y27,AB$32:AB$104) -> 0 | AC27: =SUMIF($Y$32:$Y$104,$Y27,AC$32:AC$104) -> 0 | AD27: =SUMIF($Y$32:$Y$104,$Y27,AD$32:AD$104) -> 0 | AE27: =SUMIF($Y$32:$Y$104,$Y27,AE$32:AE$104) -> 0 | AF27: =SUMIF($Y$32:$Y$104,$Y27,AF$32:AF$104) -> 0 | AG27: =SUMIF($Y$32:$Y$104,$Y27,AG$32:AG$104) -> 0 | AH27: =SUMIF($Y$32:$Y$104,$Y27,AH$32:AH$104) -> 0 | AI27: =SUMIF($Y$32:$Y$104,$Y27,AI$32:AI$104) -> 0 | ... AL27: =SUMIF($Y$32:$Y$104,$Y27,AL$32:AL$104) -> 0
F28: Allocations | G28: =SUMIFS('JDE GL Act'!$H:$H,'JDE GL Act'!$J:$J,$C$6,'JDE GL Act'!$I:$I,G$12,'JDE GL Act'!$L:$L,$F28) -> 0 | H28: =SUMIFS('JDE GL Act'!$H:$H,'JDE GL Act'!$J:$J,$C$6,'JDE GL Act'!$I:$I,H$12,'JDE GL Act'!$L:$L,$F28) -> -8553.9 | I28: =SUMIFS('JDE GL Act'!$H:$H,'JDE GL Act'!$J:$J,$C$6,'JDE GL Act'!$I:$I,I$12,'JDE GL Act'!$L:$L,$F28) -> 0 | J28: =SUMIFS('JDE GL Act'!$H:$H,'JDE GL Act'!$J:$J,$C$6,'JDE GL Act'!$I:$I,J$12,'JDE GL Act'!$L:$L,$F28) -> 0 | K28: =SUMIFS('JDE GL Act'!$H:$H,'JDE GL Act'!$J:$J,$C$6,'JDE GL Act'!$I:$I,K$12,'JDE GL Act'!$L:$L,$F28) -> 0 | L28: =SUMIFS('JDE GL Act'!$H:$H,'JDE GL Act'!$J:$J,$C$6,'JDE GL Act'!$I:$I,L$12,'JDE GL Act'!$L:$L,$F28) -> 0 | M28: =SUMIFS('JDE GL Act'!$H:$H,'JDE GL Act'!$J:$J,$C$6,'JDE GL Act'!$I:$I,M$12,'JDE GL Act'!$L:$L,$F28) -> 0 | N28: =SUMIFS('JDE GL Act'!$H:$H,'JDE GL Act'!$J:$J,$C$6,'JDE GL Act'!$I:$I,N$12,'JDE GL Act'!$L:$L,$F28) -> 0 | ... R28: =SUMIFS('JDE GL Act'!$H:$H,'JDE GL Act'!$J:$J,$C$6,'JDE GL Act'!$I:$I,R$12,'JDE GL Act'!$L:$L,$F28) -> 0 | S28: =+SUM(G28:R28) -> -8553.9 | Y28: =F28 -> Allocations | Z28: =G28 -> 0 | AA28: =H28 -> -8553.9 | AB28: =SUMIF($Y$32:$Y$104,$Y28,AB$32:AB$104) -> -1423.3333 | AC28: =SUMIF($Y$32:$Y$104,$Y28,AC$32:AC$104) -> -1423.3333 | AD28: =SUMIF($Y$32:$Y$104,$Y28,AD$32:AD$104) -> -1423.3333 | AE28: =SUMIF($Y$32:$Y$104,$Y28,AE$32:AE$104) -> -1423.3333 | AF28: =SUMIF($Y$32:$Y$104,$Y28,AF$32:AF$104) -> -1423.3333 | AG28: =SUMIF($Y$32:$Y$104,$Y28,AG$32:AG$104) -> -1423.3333 | AH28: =SUMIF($Y$32:$Y$104,$Y28,AH$32:AH$104) -> -1423.3333 | AI28: =SUMIF($Y$32:$Y$104,$Y28,AI$32:AI$104) -> -1423.3333 | ... AL28: =SUMIF($Y$32:$Y$104,$Y28,AL$32:AL$104) -> -17080
F29: Net Dept Expense | G29: =+G26+G27+G28 -> 140579.87 | H29: =+H26+H27+H28 -> 102474.03 | I29: =+I26+I27+I28 -> 0 | J29: =+J26+J27+J28 -> 0 | K29: =+K26+K27+K28 -> 0 | L29: =+L26+L27+L28 -> 0 | M29: =+M26+M27+M28 -> 0 | N29: =+N26+N27+N28 -> 0 | ... R29: =+R26+R27+R28 -> 0 | S29: =+SUM(G29:R29) -> 243053.9 | Y29: =F29 -> Net Dept Expense | Z29: =G29 -> 140579.87 | AA29: =H29 -> 102474.03 | AB29: =+AB26+AB27+AB28 -> 176149.18 | AC29: =+AC26+AC27+AC28 -> 117634.29 | AD29: =+AD26+AD27+AD28 -> 143040.69 | AE29: =+AE26+AE27+AE28 -> 165272.7 | AF29: =+AF26+AF27+AF28 -> 124036.55 | AG29: =+AG26+AG27+AG28 -> 133013.12 | AH29: =+AH26+AH27+AH28 -> 188749.18 | AI29: =+AI26+AI27+AI28 -> 124905.71 | ... AL29: =+AL26+AL27+AL28 -> 1883782.4
W31: JDE Account | X31: Account Name | Y31: BVA group | Z31: Jul | AA31: Aug | AB31: Sep | AC31: Oct | AD31: Nov | AE31: Dec | AF31: Jan | AG31: Feb | AH31: Mar | AI31: Apr | AJ31: May | AK31: Jun | AL31: Full Year
W32: 501052 | X32: IDL Mgt/Salary Wages | Y32: Wages & Salaries | Z32: 63728.039 | AA32: 58186.47 | AB32: 63578.417 | AC32: 66468.345 | AD32: 57798.561 | AE32: 66468.345 | AF32: 63578.417 | AG32: 57798.561 | AH32: 63578.417 | AI32: 63578.417 | AJ32: 60688.489 | AK32: 63578.417 | AL32: =+SUM(Z32:AK32) -> 749028.89
W33: 501050 | X33: IDL Hourly Labor Exp | Y33: Wages & Salaries | Z33: 8040.0923 | AA33: 7340.9538 | AB33: 8021.2156 | AC33: 8385.8163 | AD33: 7292.0142 | AE33: 8385.8163 | AF33: 8021.2156 | AG33: 7292.0142 | AH33: 8021.2156 | AI33: 8021.2156 | AJ33: 7656.6149 | AK33: 8021.2156 | AL33: =+SUM(Z33:AK33) -> 94499.4
W34: 501053 | X34: IDL Overtime Premium | Y34: Overtime | Z34: 641.91125 | AA34: 586.09288 | AB34: 640.40415 | AC34: 669.51343 | AD34: 582.18559 | AE34: 669.51343 | AF34: 640.40415 | AG34: 582.18559 | AH34: 640.40415 | AI34: 640.40415 | AJ34: 611.29487 | AK34: 640.40415 | AL34: =+SUM(Z34:AK34) -> 7544.7178
W35: 501062 | X35: IDL Other Fringe Ben | Y35: Fringe Benefits | Z35: 24907.835 | AA35: 23227.733 | AB35: 24862.473 | AC35: 24463.949 | AD35: 21391.26 | AE35: 22872.355 | AF35: 27719.847 | AG35: 23113.689 | AH35: 24862.473 | AI35: 24889.012 | AJ35: 23959.761 | AK35: 24889.012 | AL35: =+SUM(Z35:AK35) -> 291159.4
W36: 501705 | X36: T & E Processing Fee | Y36: Travel & Entertainment | Z36: 1770 | AA36: 0 | AB36: 1770 | AC36: 1770 | AD36: 0 | AE36: 0 | AF36: 0 | AG36: 0 | AH36: 1770 | AI36: 0 | AJ36: 0 | AK36: 0 | AL36: =+SUM(Z36:AK36) -> 7080
W37: 501804 | X37: Other Employee Exp | Y37: Employee Related Expenses | AG37: 3000 | AL37: =+SUM(Z37:AK37) -> 3000
W38: 501602 | X38: Safety Supplies | Y38: Supplies Expenses | Z38: 200 | AF38: 200 | AK38: 200 | AL38: =+SUM(Z38:AK38) -> 600
W39: 501710 | X39: Out Service-On Shore | Y39: Outside Services | AA39: 600 | AC39: 600 | AD39: 600 | AG39: 600 | AJ39: 600 | AK39: 0 | AL39: =+SUM(Z39:AK39) -> 3000
W40: 501710 | X40: Out Service-On Shore | Y40: Outside Services | AA40: 2500 | AC40: 2500 | AD40: 2500 | AG40: 2500 | AJ40: 2500 | AL40: =+SUM(Z40:AK40) -> 12500
W41: 501710 | X41: Out Service-On Shore | Y41: Outside Services | AB41: 2500 | AL41: =+SUM(Z41:AK41) -> 2500
W42: 501710 | X42: Out Service-On Shore | Y42: Outside Services | Z42: 9000 | AA42: 9000 | AB42: 9000 | AL42: =+SUM(Z42:AK42) -> 27000
W43: 501710 | X43: Out Service-On Shore | Y43: Outside Services | Z43: 6300 | AA43: 6300 | AB43: 6300 | AL43: =+SUM(Z43:AK43) -> 18900
W44: 501710 | X44: Out Service-On Shore | Y44: Outside Services | AG44: 8150 | AL44: =+SUM(Z44:AK44) -> 8150
W45: 501710 | X45: Out Service-On Shore | Y45: Outside Services | AG45: 2500 | AL45: =+SUM(Z45:AK45) -> 2500
W46: 501710 | X46: Out Service-On Shore | Y46: Outside Services | AG46: 1700 | AL46: =+SUM(Z46:AK46) -> 1700
W47: 501710 | X47: Out Service-On Shore | Y47: Outside Services | AD47: 9000 | AL47: =+SUM(Z47:AK47) -> 9000
W48: 501710 | X48: Out Service-On Shore | Y48: Outside Services | AH48: 12200 | AL48: =+SUM(Z48:AK48) -> 12200
...

Sheet JDE GL Act
G1: 19487085 | N1: =SUBTOTAL(9,N5:N6) -> 1296859.2 | Q1: Exclude: | R1: PPV
J2: Keep These Formulas | R2: MUV
A3: SAP CC | B3: Description | C3: Obj Account | D3: Keep SAP'd CCs and GL Object Accounts hard coded | J3: =VALUE(A3) -> #VALUE! | K3: =VALUE(C3) -> #VALUE! | L3: =VLOOKUP(K3,[1]Mapping!$L$3:$Q$231,4,FALSE) -> #VALUE! | R3: SLOB
P4: Business Unit | R4: DL Abs
M5: JDE GL | N5: 718193.4 | O5: Aug-Sep | P5: 732028 | R5: OH Abs
H6: =H7-H8 -> 5369023.8 | M6: SAP | N6: 578665.8 | O6: Aug-Sep | P6: 732029 | R6: FX
G7: -1820361 | H7: ='[1]Total QRA BvA'!K29 -> 5420846 | N7: =N5-N6 -> 139527.6 | P7: 732030
G8: =SUBTOTAL(9,G10:G6000) -> 51822.16 | H8: =SUBTOTAL(9,H10:H6000) -> 51822.16
A9: Business Unit | B9: Business Unit Description | C9: Obj Acct | D9: Account Description | E9: Period | F9: Currency Code | G9: Amount in LC | H9: Amount in USD | I9: Month | J9: SAP Legacy CC | K9: SAP Legacy GL | L9: Mapping Rec | M9: Source
A10: 2000113000 | B10: SC - QRA Admin | C10: 600019 | D10: Oth Fringe Bene Exp | E10: 1 | F10: Fringe Benefits | G10: 28.54 | H10: 28.54 | I10: =VLOOKUP(E10,[1]Mapping!$A$3:$B$14,2,FALSE) -> Jul | J10: =VALUE(A10) -> 2000113000 | K10: =VALUE(C10) -> 600019 | L10: =VLOOKUP(K10,[1]Mapping!$J$3:$Q$351,8,FALSE) -> Fringe Benefits | M10: JDE_GL | O10: 01110551
A11: 2000113000 | B11: SC - QRA Admin | C11: 501709 | D11: NonIMExtConsultSrvs-Cont | E11: 1 | F11: Outside Services | G11: 563.06 | H11: 563.06 | I11: =VLOOKUP(E11,[1]Mapping!$A$3:$B$14,2,FALSE) -> Jul | J11: =VALUE(A11) -> 2000113000 | K11: =VALUE(C11) -> 501709 | L11: =VLOOKUP(K11,[1]Mapping!$J$3:$Q$351,8,FALSE) -> Outside Services | M11: JDE_GL
A12: 2000113000 | B12: SC - QRA Admin | C12: 600001 | D12: Salary Expense | E12: 1 | F12: Wages & Salaries | G12: 14051.6 | H12: 14051.6 | I12: =VLOOKUP(E12,[1]Mapping!$A$3:$B$14,2,FALSE) -> Jul | J12: =VALUE(A12) -> 2000113000 | K12: =VALUE(C12) -> 600001 | L12: =VLOOKUP(K12,[1]Mapping!$J$3:$Q$351,8,FALSE) -> Wages & Salaries | M12: JDE_GL
A13: 2000113000 | B13: SC - QRA Admin | C13: 600011 | D13: 401k ER Match | E13: 1 | F13: Fringe Benefits | G13: 568.61 | H13: 568.61 | I13: =VLOOKUP(E13,[1]Mapping!$A$3:$B$14,2,FALSE) -> Jul | J13: =VALUE(A13) -> 2000113000 | K13: =VALUE(C13) -> 600011 | L13: =VLOOKUP(K13,[1]Mapping!$J$3:$Q$351,8,FALSE) -> Fringe Benefits | M13: JDE_GL
A14: 2000113000 | B14: SC - QRA Admin | C14: 600013 | D14: Health Insurance Exp | E14: 1 | F14: Fringe Benefits | G14: 1464.92 | H14: 1464.92 | I14: =VLOOKUP(E14,[1]Mapping!$A$3:$B$14,2,FALSE) -> Jul | J14: =VALUE(A14) -> 2000113000 | K14: =VALUE(C14) -> 600013 | L14: =VLOOKUP(K14,[1]Mapping!$J$3:$Q$351,8,FALSE) -> Fringe Benefits | M14: JDE_GL
A15: 2000113000 | B15: SC - QRA Admin | C15: 600018 | D15: SS/Medicare Expense | E15: 1 | F15: Fringe Benefits | G15: 1049.28 | H15: 1049.28 | I15: =VLOOKUP(E15,[1]Mapping!$A$3:$B$14,2,FALSE) -> Jul | J15: =VALUE(A15) -> 2000113000 | K15: =VALUE(C15) -> 600018 | L15: =VLOOKUP(K15,[1]Mapping!$J$3:$Q$351,8,FALSE) -> Fringe Benefits | M15: JDE_GL
A16: 2000113000 | B16: SC - QRA Admin | C16: 600022 | D16: Disability ER | E16: 1 | F16: Fringe Benefits | G16: 36.98 | H16: 36.98 | I16: =VLOOKUP(E16,[1]Mapping!$A$3:$B$14,2,FALSE) -> Jul | J16: =VALUE(A16) -> 2000113000 | K16: =VALUE(C16) -> 600022 | L16: =VLOOKUP(K16,[1]Mapping!$J$3:$Q$351,8,FALSE) -> Fringe Benefits | M16: JDE_GL
A17: 2000113000 | B17: SC - QRA Admin | C17: 600020 | D17: MIP Bonus Expense | E17: 1 | F17: Fringe Benefits | G17: 1323.7 | H17: 1323.7 | I17: =VLOOKUP(E17,[1]Mapping!$A$3:$B$14,2,FALSE) -> Jul | J17: =VALUE(A17) -> 2000113000 | K17: =VALUE(C17) -> 600020 | L17: =VLOOKUP(K17,[1]Mapping!$J$3:$Q$351,8,FALSE) -> Fringe Benefits | M17: JDE_GL
A18: 2000113000 | B18: SC - QRA Admin | C18: 600055 | D18: MIP Bonus Fringe Exp | E18: 1 | F18: Fringe Benefits | G18: 105.9 | H18: 105.9 | I18: =VLOOKUP(E18,[1]Mapping!$A$3:$B$14,2,FALSE) -> Jul | J18: =VALUE(A18) -> 2000113000 | K18: =VALUE(C18) -> 600055 | L18: =VLOOKUP(K18,[1]Mapping!$J$3:$Q$351,8,FALSE) -> Fringe Benefits | M18: JDE_GL
A19: 2000113000 | B19: SC - QRA Admin | C19: 600026 | D19: HSA/FSA | E19: 1 | F19: Fringe Benefits | G19: 1082.48 | H19: 1082.48 | I19: =VLOOKUP(E19,[1]Mapping!$A$3:$B$14,2,FALSE) -> Jul | J19: =VALUE(A19) -> 2000113000 | K19: =VALUE(C19) -> 600026 | L19: =VLOOKUP(K19,[1]Mapping!$J$3:$Q$351,8,FALSE) -> Fringe Benefits | M19: JDE_GL
A20: 2000113001 | B20: SC - NA Man. QRA | C20: 600019 | D20: Oth Fringe Bene Exp | E20: 1 | F20: Fringe Benefits | G20: 113.12 | H20: 113.12 | I20: =VLOOKUP(E20,[1]Mapping!$A$3:$B$14,2,FALSE) -> Jul | J20: =VALUE(A20) -> 2000113001 | K20: =VALUE(C20) -> 600019 | L20: =VLOOKUP(K20,[1]Mapping!$J$3:$Q$351,8,FALSE) -> Fringe Benefits | M20: JDE_GL
A21: 2000113001 | B21: SC - NA Man. QRA | C21: 600001 | D21: Salary Expense | E21: 1 | F21: Wages & Salaries | G21: 67010.18 | H21: 67010.18 | I21: =VLOOKUP(E21,[1]Mapping!$A$3:$B$14,2,FALSE) -> Jul | J21: =VALUE(A21) -> 2000113001 | K21: =VALUE(C21) -> 600001 | L21: =VLOOKUP(K21,[1]Mapping!$J$3:$Q$351,8,FALSE) -> Wages & Salaries | M21: JDE_GL
A22: 2000113001 | B22: SC - NA Man. QRA | C22: 501053 | D22: IDL Overtime Premium | E22: 1 | F22: Overtime | G22: 3.36 | H22: 3.36 | I22: =VLOOKUP(E22,[1]Mapping!$A$3:$B$14,2,FALSE) -> Jul | J22: =VALUE(A22) -> 2000113001 | K22: =VALUE(C22) -> 501053 | L22: =VLOOKUP(K22,[1]Mapping!$J$3:$Q$351,8,FALSE) -> Overtime | M22: JDE_GL
... A385: 1110073 | B385: Post Market Surveillance | C385: 501709 | D385: NonIMExtConsultSrvs-Cont | E385: 1 | F385: Outside Services | G385: 1331 | H385: 1331 | I385: =VLOOKUP(E385,[1]Mapping!$A$3:$B$14,2,FALSE) -> Jul | J385: =VALUE(A385) -> 1110073 | K385: =VALUE(C385) -> 501709 | L385: =VLOOKUP(K385,[1]Mapping!$J$3:$Q$351,8,FALSE) -> Outside Services | M385: JDE_GL
A386: 1110073 | B386: Post Market Surveillance | C386: 501017 | D386: DL - HSA / FSA | E386: 1 | F386: Fringe Benefits | G386: -236.6 | H386: -236.6 | I386: =VLOOKUP(E386,[1]Mapping!$A$3:$B$14,2,FALSE) -> Jul | J386: =VALUE(A386) -> 1110073 | K386: =VALUE(C386) -> 501017 | L386: =VLOOKUP(K386,[1]Mapping!$J$3:$Q$351,8,FALSE) -> Fringe Benefits | M386: JDE_GL | N386: CAD | O386: A
A387: 1110073 | B387: Post Market Surveillance | C387: 607130 | D387: Sales Tax Expense | E387: 1 | F387: Other | G387: 18.29 | H387: 18.29 | I387: =VLOOKUP(E387,[1]Mapping!$A$3:$B$14,2,FALSE) -> Jul | J387: =VALUE(A387) -> 1110073 | K387: =VALUE(C387) -> 607130 | L387: =VLOOKUP(K387,[1]Mapping!$J$3:$Q$351,8,FALSE) -> Other | M387: JDE_GL | N387: CAD | O387: A
A388: 1110073 | B388: Post Market Surveillance | C388: 600020 | D388: MIP Bonus Expense | E388: 1 | F388: Fringe Benefits | G388: 20605.35 | H388: 20605.35 | I388: =VLOOKUP(E388,[1]Mapping!$A$3:$B$14,2,FALSE) -> Jul | J388: =VALUE(A388) -> 1110073 | K388: =VALUE(C388) -> 600020 | L388: =VLOOKUP(K388,[1]Mapping!$J$3:$Q$351,8,FALSE) -> Fringe Benefits | M388: JDE_GL | N388: CAD | O388: A
A389: 1110073 | B389: Post Market Surveillance | C389: 600055 | D389: MIP Bonus Fringe Exp | E389: 1 | F389: Fringe Benefits | G389: 1648.43 | H389: 1648.43 | I389: =VLOOKUP(E389,[1]Mapping!$A$3:$B$14,2,FALSE) -> Jul | J389: =VALUE(A389) -> 1110073 | K389: =VALUE(C389) -> 600055 | L389: =VLOOKUP(K389,[1]Mapping!$J$3:$Q$351,8,FALSE) -> Fringe Benefits | M389: JDE_GL | N389: CAD | O389: A
A390: 1110073 | B390: Post Market Surveillance | C390: 501070 | D390: IDL HSA/FSA | E390: 1 | F390: Fringe Benefits | G390: 6480 | H390: 6480 | I390: =VLOOKUP(E390,[1]Mapping!$A$3:$B$14,2,FALSE) -> Jul | J390: =VALUE(A390) -> 1110073 | K390: =VALUE(C390) -> 501070 | L390: =VLOOKUP(K390,[1]Mapping!$J$3:$Q$351,8,FALSE) -> Fringe Benefits | M390: JDE_GL | N390: CAD | O390: A
A391: 1110080 | B391: Quality Engineering | C391: 501050 | D391: IDL Hourly Labor Exp | E391: 1 | F391: Wages & Salaries | G391: 83356.52 | H391: 83356.52 | I391: =VLOOKUP(E391,[1]Mapping!$A$3:$B$14,2,FALSE) -> Jul | J391: =VALUE(A391) -> 1110080 | K391: =VALUE(C391) -> 501050 | L391: =VLOOKUP(K391,[1]Mapping!$J$3:$Q$351,8,FALSE) -> Wages & Salaries | M391: JDE_GL | N391: CAD | O391: A
A392: 1110080 | B392: Quality Engineering | C392: 501051 | D392: IDL PTO Expense | E392: 1 | F392: Wages & Salaries | G392: 1251.32 | H392: 1251.32 | I392: =VLOOKUP(E392,[1]Mapping!$A$3:$B$14,2,FALSE) -> Jul | J392: =VALUE(A392) -> 1110080 | K392: =VALUE(C392) -> 501051 | L392: =VLOOKUP(K392,[1]Mapping!$J$3:$Q$351,8,FALSE) -> Wages & Salaries | M392: JDE_GL | N392: CAD | O392: A
A393: 1110080 | B393: Quality Engineering | C393: 501058 | D393: IDL SS/Medicare Expe | E393: 1 | F393: Fringe Benefits | G393: 6373.95 | H393: 6373.95 | I393: =VLOOKUP(E393,[1]Mapping!$A$3:$B$14,2,FALSE) -> Jul | J393: =VALUE(A393) -> 1110080 | K393: =VALUE(C393) -> 501058 | L393: =VLOOKUP(K393,[1]Mapping!$J$3:$Q$351,8,FALSE) -> Fringe Benefits | M393: JDE_GL | N393: JPY | O393: A
A394: 1110080 | B394: Quality Engineering | C394: 501062 | D394: IDL Other Fringe Ben | E394: 1 | F394: Fringe Benefits | G394: 153.48 | H394: 153.48 | I394: =VLOOKUP(E394,[1]Mapping!$A$3:$B$14,2,FALSE) -> Jul | J394: =VALUE(A394) -> 1110080 | K394: =VALUE(C394) -> 501062 | L394: =VLOOKUP(K394,[1]Mapping!$J$3:$Q$351,8,FALSE) -> Fringe Benefits | M394: JDE_GL | N394: EUR | O394: A
A395: 1110080 | B395: Quality Engineering | C395: 501063 | D395: IDL Health Ins Exp | E395: 1 | F395: Fringe Benefits | G395: 4940.73 | H395: 4940.73 | I395: =VLOOKUP(E395,[1]Mapping!$A$3:$B$14,2,FALSE) -> Jul | J395: =VALUE(A395) -> 1110080 | K395: =VALUE(C395) -> 501063 | L395: =VLOOKUP(K395,[1]Mapping!$J$3:$Q$351,8,FALSE) -> Fringe Benefits | M395: JDE_GL | N395: EUR | O395: A
A396: 1110080 | B396: Quality Engineering | C396: 501065 | D396: IDL - Disability | E396: 1 | F396: Fringe Benefits | G396: 204.54 | H396: 204.54 | I396: =VLOOKUP(E396,[1]Mapping!$A$3:$B$14,2,FALSE) -> Jul | J396: =VALUE(A396) -> 1110080 | K396: =VALUE(C396) -> 501065 | L396: =VLOOKUP(K396,[1]Mapping!$J$3:$Q$351,8,FALSE) -> Fringe Benefits | M396: JDE_GL
A397: 1110080 | B397: Quality Engineering | C397: 501069 | D397: IDL 401k ER Match | E397: 1 | F397: Fringe Benefits | G397: 4133.89 | H397: 4133.89 | I397: =VLOOKUP(E397,[1]Mapping!$A$3:$B$14,2,FALSE) -> Jul | J397: =VALUE(A397) -> 1110080 | K397: =VALUE(C397) -> 501069 | L397: =VLOOKUP(K397,[1]Mapping!$J$3:$Q$351,8,FALSE) -> Fringe Benefits | M397: JDE_GL
A398: 1110080 | B398: Quality Engineering | C398: 608533 | D398: Miscellaneous Expense | E398: 1 | F398: Other | G398: 0 | H398: 0 | I398: =VLOOKUP(E398,[1]Mapping!$A$3:$B$14,2,FALSE) -> Jul | J398: =VALUE(A398) -> 1110080 | K398: =VALUE(C398) -> 608533 | L398: =VLOOKUP(K398,[1]Mapping!$J$3:$Q$351,8,FALSE) -> Other | M398: JDE_GL
A399: 1110080 | B399: Quality Engineering | C399: 600044 | D399: Meals - Travel | E399: 1 | F399: Travel & Entertainment | G399: 0 | H399: 0 | I399: =VLOOKUP(E399,[1]Mapping!$A$3:$B$14,2,FALSE) -> Jul | J399: =VALUE(A399) -> 1110080 | K399: =VALUE(C399) -> 600044 | L399: =VLOOKUP(K399,[1]Mapping!$J$3:$Q$351,8,FALSE) -> Travel & Entertainment | M399: JDE_GL
A400: 1110080 | B400: Quality Engineering | C400: 600027 | D400: Auto Expense | E400: 1 | F400: Travel & Entertainment | G400: 0 | H400: 0 | I400: =VLOOKUP(E400,[1]Mapping!$A$3:$B$14,2,FALSE) -> Jul | J400: =VALUE(A400) -> 1110080 | K400: =VALUE(C400) -> 600027 | L400: =VLOOKUP(K400,[1]Mapping!$J$3:$Q$351,8,FALSE) -> Travel & Entertainment | M400: JDE_GL
A401: 1110080 | B401: Quality Engineering | C401: 600029 | D401: Lodging Expense | E401: 1 | F401: Travel & Entertainment | G401: 0 | H401: 0 | I401: =VLOOKUP(E401,[1]Mapping!$A$3:$B$14,2,FALSE) -> Jul | J401: =VALUE(A401) -> 1110080 | K401: =VALUE(C401) -> 600029 | L401: =VLOOKUP(K401,[1]Mapping!$J$3:$Q$351,8,FALSE) -> Travel & Entertainment | M401: JDE_GL
A402: 1110080 | B402: Quality Engineering | C402: 600020 | D402: MIP Bonus Expense | E402: 1 | F402: Fringe Benefits | G402: 10756.02 | H402: 10756.02 | I402: =VLOOKUP(E402,[1]Mapping!$A$3:$B$14,2,FALSE) -> Jul | J402: =VALUE(A402) -> 1110080 | K402: =VALUE(C402) -> 600020 | L402: =VLOOKUP(K402,[1]Mapping!$J$3:$Q$351,8,FALSE) -> Fringe Benefits | M402: JDE_GL
...
